Workbook

Sheet P&L
B3: Income Statement | C3: 2021 | D3: =C3+1 -> 2022 | E3: =D3+1 -> 2023 | F3: =E3+1 -> 2024 | G3: =F3+1 -> 2025 | H3: =G3+1 -> 2026 | I3: =H3+1 -> 2027 | J3: =I3+1 -> 2028 | K3: =J3+1 -> 2029
B4: Year weight | C4: 1 | D4: =C4+1 -> 2 | E4: =D4+1 -> 3 | F4: =E4+1 -> 4 | G4: =F4+1 -> 5 | H4: =G4+1 -> 6 | I4: =H4+1 -> 7 | J4: =I4+1 -> 8 | K4: =J4+1 -> 9
B5: Revenues | C5: 29697.844 | D5: 31615.55 | E5: 33723.297 | F5: 39000.966 | G5: =Assumptions!G25 -> 45091.395 | H5: =Assumptions!H25 -> 50502.363 | I5: =Assumptions!I25 -> 55047.575 | J5: =Assumptions!J25 -> 59451.381 | K5: =Assumptions!K25 -> 64207.492
B6: Cost of revenues | C6: 17332.683 | D6: 19168.285 | E6: 19715.368 | F6: 21038.464 | G6: =Assumptions!G50 -> 22276.654 | H6: =Assumptions!H50 -> 23962.97 | I6: =Assumptions!I50 -> 26414.123 | J6: =Assumptions!J50 -> 29234.393 | K6: =Assumptions!K50 -> 31488.001
B7: Sales and marketing | C7: 2545.146 | D7: 2530.502 | E7: 2657.883 | F7: 2917.554 | G7: =Assumptions!G33 -> 3017.4712 | H7: =Assumptions!H33 -> 3251.2504 | I7: =Assumptions!I33 -> 3497.4483 | J7: =Assumptions!J33 -> 3759.0112 | K7: =Assumptions!K33 -> 4036.9617
B8: Technology and development | C8: 2273.885 | D8: 2711.041 | E8: 2675.758 | F8: 2925.295 | G8: =Assumptions!G35 -> 3401.6211 | H8: =Assumptions!H35 -> 3669.1053 | I8: =Assumptions!I35 -> 3958.7925 | J8: =Assumptions!J35 -> 4265.6554 | K8: =Assumptions!K35 -> 4594.5765
B9: General and administrative | C9: 1351.621 | D9: 1572.891 | E9: 1720.285 | F9: 1702.039 | G9: =Assumptions!G37 -> 1803.7232 | H9: =Assumptions!H37 -> 1886.8944 | I9: =Assumptions!I37 -> 1974.0205 | J9: =Assumptions!J37 -> 2063.6667 | K9: =Assumptions!K37 -> 2155.0213
B10: Operating income | C10: =C5-SUM(C6:C9) -> 6194.509 | D10: =D5-SUM(D6:D9) -> 5632.831 | E10: =E5-SUM(E6:E9) -> 6954.003 | F10: =F5-SUM(F6:F9) -> 10417.614 | G10: =G5-SUM(G6:G9) -> 14591.926 | H10: =H5-SUM(H6:H9) -> 17732.143 | I10: =I5-SUM(I6:I9) -> 19203.192 | J10: =J5-SUM(J6:J9) -> 20128.655 | K10: =K5-SUM(K6:K9) -> 21932.931
B11: Other income (expense):
B12: Interest expense | C12: -765.62 | D12: -706.212 | E12: -699.826 | F12: -718.733 | G12: =Assumptions!G96 -> -738.12906 | H12: =Assumptions!H96 -> -717.74724 | I12: =Assumptions!I96 -> -700.12335 | J12: =Assumptions!J96 -> -679.40595 | K12: =Assumptions!K96 -> -660.89398
B13: Interest and other income (expense) | C13: 411.214 | D13: 337.31 | E13: -48.772 | F13: 266.776 | G13: 266.776 | H13: 266.776 | I13: 266.776 | J13: 266.776 | K13: 266.776
B14: Income before income taxes | C14: =C10+C12+C13 -> 5840.103 | D14: =D10+D12+D13 -> 5263.929 | E14: =E10+E12+E13 -> 6205.405 | F14: =F10+F12+F13 -> 9965.657 | G14: =G10+G12+G13 -> 14120.573 | H14: =H10+H12+H13 -> 17281.171 | I14: =I10+I12+I13 -> 18769.844 | J14: =J10+J12+J13 -> 19716.025 | K14: =K10+K12+K13 -> 21538.813
B15: Provision for income taxes | C15: -723.875 | D15: -772.005 | E15: -797.415 | F15: -1254.026 | G15: =Assumptions!G42 -> -1776.8588 | H15: =Assumptions!H42 -> -2174.5719 | I15: =Assumptions!I42 -> -2361.8987 | J15: =Assumptions!J42 -> -2480.9612 | K15: =Assumptions!K42 -> -2710.3312
B16: Net income | C16: =C14+C15 -> 5116.228 | D16: =D14+D15 -> 4491.924 | E16: =E14+E15 -> 5407.99 | F16: =F14+F15 -> 8711.631 | G16: =G14+G15 -> 12343.714 | H16: =H14+H15 -> 15106.599 | I16: =I14+I15 -> 16407.946 | J16: =J14+J15 -> 17235.064 | K16: =K14+K15 -> 18828.482
B17: Earnings per share:
B18: Basic | C18: =C$16/C21 -> 1.1545008 | D18: =D$16/D21 -> 1.0101066 | E18: =E$16/E21 -> 1.2247158 | F18: =F$16/F21 -> 2.0282295 | G18: =G$16/G21 -> 2.9195815 | H18: =H$16/H21 -> 3.6313737 | I18: =I$16/I21 -> 4.0093307 | J18: =J$16/J21 -> 4.2823147 | K18: =K$16/K21 -> 4.7582123
B19: Diluted | C19: =C$16/C22 -> 1.1235271 | D19: =D$16/D22 -> 0.99535199 | E19: =E$16/E22 -> 1.2031177 | F19: =F$16/F22 -> 1.9832471 | G19: =G$16/G22 -> 2.8647849 | H19: =H$16/H22 -> 3.5579458 | I19: =I$16/I22 -> 3.9248878 | J19: =J$16/J22 -> 4.1938225 | K19: =K$16/K22 -> 4.6566833
B20: Weighted-average shares(millions)
B21: Basic | C21: 4431.55 | D21: 4446.98 | E21: 4415.71 | F21: 4295.19 | G21: =F21-Assumptions!G129 -> 4227.9051 | H21: =G21-Assumptions!H129 -> 4160.0234 | I21: =H21-Assumptions!I129 -> 4092.44 | J21: =I21-Assumptions!J129 -> 4024.7075 | K21: =J21-Assumptions!K129 -> 3957.0496
B22: Diluted | C22: 4553.72 | D22: 4512.9 | E22: 4494.98 | F22: 4392.61 | G22: =G21+Assumptions!G130 -> 4308.7751 | H22: =H21+Assumptions!H130 -> 4245.8767 | I22: =I21+Assumptions!I130 -> 4180.4878 | J22: =J21+Assumptions!J130 -> 4109.6312 | K22: =K21+Assumptions!K130 -> 4043.3245

Sheet BS
B3: Balance Sheet | C3: 2021 | D3: =C3+1 -> 2022 | E3: =D3+1 -> 2023 | F3: =E3+1 -> 2024 | G3: =F3+1 -> 2025 | H3: =G3+1 -> 2026 | I3: =H3+1 -> 2027 | J3: =I3+1 -> 2028 | K3: =J3+1 -> 2029
B4: Year weight | C4: 1 | D4: =C4+1 -> 2 | E4: =D4+1 -> 3 | F4: =E4+1 -> 4 | G4: =F4+1 -> 5 | H4: =G4+1 -> 6 | I4: =H4+1 -> 7 | J4: =I4+1 -> 8 | K4: =J4+1 -> 9
B5: ASSETS
B6: Current assets:
B7: Cash and cash equivalents | C7: 6027.804 | D7: 5147.176 | E7: 7116.913 | F7: 7804.733 | G7: =CFS!D34 -> 10977.516 | H7: =CFS!E34 -> 15731.529 | I7: =CFS!F34 -> 21618.101 | J7: =CFS!G34 -> 28984.465 | K7: =CFS!H34 -> 37271.778
B8: Short-term investments | C8: 0 | D8: 911.276 | E8: 20.973 | F8: 1779.006 | G8: 1779.006 | H8: 1779.006 | I8: 1779.006 | J8: 1779.006 | K8: 1779.006
B9: Other current assets | C9: 2042.021 | D9: 3208.021 | E9: 2780.247 | F9: 3516.64 | G9: =Assumptions!G82 -> 3620.1031 | H9: =Assumptions!H82 -> 3852.4835 | I9: =Assumptions!I82 -> 3990.886 | J9: =Assumptions!J82 -> 4120.8532 | K9: =Assumptions!K82 -> 4291.3342
B10: Total current assets | C10: =SUM(C7:C9) -> 8069.825 | D10: =SUM(D7:D9) -> 9266.473 | E10: =SUM(E7:E9) -> 9918.133 | F10: =SUM(F7:F9) -> 13100.379 | G10: =SUM(G7:G9) -> 16376.626 | H10: =SUM(H7:H9) -> 21363.018 | I10: =SUM(I7:I9) -> 27387.993 | J10: =SUM(J7:J9) -> 34884.324 | K10: =SUM(K7:K9) -> 43342.118
B11: Content assets, net | C11: 30919.539 | D11: 32736.713 | E11: 31658.056 | F11: 32452.462 | G11: =Assumptions!G59 -> 34923.151 | H11: =Assumptions!H59 -> 38715.954 | I11: =Assumptions!I59 -> 42869.673 | J11: =Assumptions!J59 -> 46250.111 | K11: =Assumptions!K59 -> 50227.328
B12: Property and equipment, net | C12: 1323.453 | D12: 1398.257 | E12: 1491.444 | F12: 1593.756 | G12: =Assumptions!G68 -> 1793.8909 | H12: =Assumptions!H68 -> 1964.0907 | I12: =Assumptions!I68 -> 2143.778 | J12: =Assumptions!J68 -> 2341.8125 | K12: =Assumptions!K68 -> 2563.6365
B13: Other non-current assets | C13: 4271.846 | D13: 5193.325 | E13: 5664.359 | F13: 6483.777 | G13: 6483.777 | H13: 6483.777 | I13: 6483.777 | J13: 6483.777 | K13: 6483.777
B14: Total assets | C14: =SUM(C10,C11:C13) -> 44584.663 | D14: =SUM(D10,D11:D13) -> 48594.768 | E14: =SUM(E10,E11:E13) -> 48731.992 | F14: =SUM(F10,F11:F13) -> 53630.374 | G14: =SUM(G10,G11:G13) -> 59577.445 | H14: =SUM(H10,H11:H13) -> 68526.84 | I14: =SUM(I10,I11:I13) -> 78885.222 | J14: =SUM(J10,J11:J13) -> 89960.025 | K14: =SUM(K10,K11:K13) -> 102616.86
B16: LIABILITIES AND STOCKHOLDERS' EQUITY
B17: Current liabilities:
B18: Current content liabilities | C18: 4292.967 | D18: 4480.15 | E18: 4466.47 | F18: 4393.681 | G18: 4393.681 | H18: 4393.681 | I18: 4393.681 | J18: 4393.681 | K18: 4393.681
B19: Accounts payable | C19: 837.483 | D19: 671.513 | E19: 747.412 | F19: 899.909 | G19: =Assumptions!G71 -> 850.20531 | H19: =Assumptions!H71 -> 905.01131 | I19: =Assumptions!I71 -> 1013.2726 | J19: =Assumptions!J71 -> 1113.7704 | K19: =Assumptions!K71 -> 1198.9166
B20: Accrued expenses and other liabilities | C20: 1449.351 | D20: 1514.65 | E20: 1803.96 | F20: 2156.544 | G20: =Assumptions!G101 -> 2053.0641 | H20: =Assumptions!H101 -> 2231.5739 | I20: =Assumptions!I101 -> 2462.7719 | J20: =Assumptions!J101 -> 2648.2958 | K20: =Assumptions!K101 -> 2768.708
B21: Deferred revenue | C21: 1209.342 | D21: 1264.661 | E21: 1442.969 | F21: 1520.813 | G21: =Assumptions!G104 -> 1831.9 | H21: =Assumptions!H104 -> 2050.5265 | I21: =Assumptions!I104 -> 2243.3496 | J21: =Assumptions!J104 -> 2392.5632 | K21: =Assumptions!K104 -> 2604.0298
B22: Short-term debt | C22: 699.823 | D22: 0 | E22: 399.844 | F22: 1784.453 | G22: 0 | H22: 0 | I22: 0 | J22: 0 | K22: 0
B23: Total current liabilities | C23: =SUM(C18:C22) -> 8488.966 | D23: =SUM(D18:D22) -> 7930.974 | E23: =SUM(E18:E22) -> 8860.655 | F23: =SUM(F18:F22) -> 10755.4 | G23: =SUM(G18:G22) -> 9128.8504 | H23: =SUM(H18:H22) -> 9580.7927 | I23: =SUM(I18:I22) -> 10113.075 | J23: =SUM(J18:J22) -> 10548.31 | K23: =SUM(K18:K22) -> 10965.335
B24: Non-current content liabilities | C24: 3094.213 | D24: 3081.277 | E24: 2578.173 | F24: 1780.806 | G24: 1780.806 | H24: 1780.806 | I24: 1780.806 | J24: 1780.806 | K24: 1780.806
B25: Long-term debt | C25: 14693.072 | D25: 14353.076 | E25: 14143.417 | F25: 13798.351 | G25: =Assumptions!G93 -> 15182.804 | H25: =Assumptions!H93 -> 14782.804 | I25: =Assumptions!I93 -> 14382.804 | J25: =Assumptions!J93 -> 13982.804 | K25: =Assumptions!K93 -> 13582.804
B26: Other non-current liabilities | C26: 2459.164 | D26: 2452.04 | E26: 2561.434 | F26: 2552.25 | G26: 2552.25 | H26: 2552.25 | I26: 2552.25 | J26: 2552.25 | K26: 2552.25
B27: Total liabilities | C27: =SUM(C24:C26) -> 20246.449 | D27: =SUM(D24:D26) -> 19886.393 | E27: =SUM(E24:E26) -> 19283.024 | F27: =SUM(F24:F26) -> 18131.407 | G27: =SUM(G24:G26) -> 19515.86 | H27: =SUM(H24:H26) -> 19115.86 | I27: =SUM(I24:I26) -> 18715.86 | J27: =SUM(J24:J26) -> 18315.86 | K27: =SUM(K24:K26) -> 17915.86
B28: Stocksholders equity | C28: 4024.561 | D28: 4637.601 | E28: 5145.172 | F28: 6252.126 | G28: 6252.126 | H28: 6252.126 | I28: 6252.126 | J28: 6252.126 | K28: 6252.126
B29: Treasury stock | C29: -824.19 | D29: -824.19 | E29: -6922.2 | F29: -13171.638 | G29: =-13171.638-Assumptions!G127 -> -19326.185 | H29: =G29-Assumptions!H127 -> -25535.331 | I29: =H29-Assumptions!I127 -> -31717.177 | J29: =I29-Assumptions!J127 -> -37912.673 | K29: =J29-Assumptions!K127 -> -44101.345
B30: Other comprehensive loss | C30: -40.495 | D30: -217.306 | E30: -223.945 | F30: 362.162 | G30: 362.162 | H30: 362.162 | I30: 362.162 | J30: 362.162 | K30: 362.162
B31: Retained earnings | C31: 12689.372 | D31: 17181.296 | E31: 22589.286 | F31: 31300.917 | G31: =F31+'P&L'!G16 -> 43644.631 | H31: =G31+'P&L'!H16 -> 58751.23 | I31: =H31+'P&L'!I16 -> 75159.176 | J31: =I31+'P&L'!J16 -> 92394.24 | K31: =J31+'P&L'!K16 -> 111222.72
B32: Total shareholders equity | C32: =SUM(C28:C31) -> 15849.248 | D32: =SUM(D28:D31) -> 20777.401 | E32: =SUM(E28:E31) -> 20588.313 | F32: =SUM(F28:F31) -> 24743.567 | G32: =SUM(G28:G31) -> 30932.734 | H32: =SUM(H28:H31) -> 39830.187 | I32: =SUM(I28:I31) -> 50056.287 | J32: =SUM(J28:J31) -> 61095.854 | K32: =SUM(K28:K31) -> 73735.665
B33: Total liabilities and shareholders equity | C33: =SUM(C23,C27,C32) -> 44584.663 | D33: =SUM(D23,D27,D32) -> 48594.768 | E33: =SUM(E23,E27,E32) -> 48731.992 | F33: =SUM(F23,F27,F32) -> 53630.374 | G33: =SUM(G23,G27,G32) -> 59577.445 | H33: =SUM(H23,H27,H32) -> 68526.84 | I33: =SUM(I23,I27,I32) -> 78885.222 | J33: =SUM(J23,J27,J32) -> 89960.025 | K33: =SUM(K23,K27,K32) -> 102616.86
B35: Check | C35: =C14-C33 -> 0 | D35: =D14-D33 -> 0 | E35: =E14-E33 -> 0 | F35: =F14-F33 -> 0 | G35: =G14-G33 -> 0 | H35: =H14-H33 -> 0 | I35: =I14-I33 -> 0 | J35: =J14-J33 -> 0 | K35: =K14-K33 -> 0

Sheet CFS
B3: Cash Flow Statement | C3: 2024 | D3: =C3+1 -> 2025 | E3: =D3+1 -> 2026 | F3: =E3+1 -> 2027 | G3: =F3+1 -> 2028 | H3: =G3+1 -> 2029
B5: Cash Flow from operating activities
B6: Net income | D6: ='P&L'!G16 -> 12343.714 | E6: ='P&L'!H16 -> 15106.599 | F6: ='P&L'!I16 -> 16407.946 | G6: ='P&L'!J16 -> 17235.064 | H6: ='P&L'!K16 -> 18828.482
B7: Additions to content assets | D7: =-Assumptions!G54 -> -17500 | E7: =-Assumptions!H54 -> -19803.092 | F7: =-Assumptions!I54 -> -21949.351 | G7: =-Assumptions!J54 -> -23363.54 | H7: =-Assumptions!K54 -> -25337.174
B8: Amortization | D8: =Assumptions!G49 -> 15029.311 | E8: =Assumptions!H49 -> 16010.289 | F8: =Assumptions!I49 -> 17795.632 | G8: =Assumptions!J49 -> 19983.102 | H8: =Assumptions!K49 -> 21359.957
B9: Accounts payables | D9: =BS!G19-BS!F19 -> -49.703695 | E9: =BS!H19-BS!G19 -> 54.806003 | F9: =BS!I19-BS!H19 -> 108.26129 | G9: =BS!J19-BS!I19 -> 100.49782 | H9: =BS!K19-BS!J19 -> 85.146175
B10: Other current assets | D10: =BS!F9-BS!G9 -> -103.46314 | E10: =BS!G9-BS!H9 -> -232.38038 | F10: =BS!H9-BS!I9 -> -138.40246 | G10: =BS!I9-BS!J9 -> -129.96719 | H10: =BS!J9-BS!K9 -> -170.48099
B11: Accrued expenses and other liabilities | D11: =BS!G20-BS!F20 -> -103.47989 | E11: =BS!H20-BS!G20 -> 178.50976 | F11: =BS!I20-BS!H20 -> 231.19801 | G11: =BS!J20-BS!I20 -> 185.52389 | H11: =BS!K20-BS!J20 -> 120.41226
B12: Deferred revenue | D12: =BS!G21-BS!F21 -> 311.087 | E12: =BS!H21-BS!G21 -> 218.62648 | F12: =BS!I21-BS!H21 -> 192.82312 | G12: =BS!J21-BS!I21 -> 149.21363 | H12: =BS!K21-BS!J21 -> 211.46656
B13: PPE Depreciation | D13: =Assumptions!G48 -> 387.92581 | E13: =Assumptions!H48 -> 430.06586 | F13: =Assumptions!I48 -> 460.69488 | G13: =Assumptions!J48 -> 512.86422 | H13: =Assumptions!K48 -> 556.98591
B14: CFO | D14: =SUM(D6:D13) -> 10315.391 | E14: =SUM(E6:E13) -> 11963.424 | F14: =SUM(F6:F13) -> 13108.801 | G14: =SUM(G6:G13) -> 14672.758 | H14: =SUM(H6:H13) -> 15654.795
B16: Cash Flow from Investing activities
B17: PPE Additions | D17: =-Assumptions!G63 -> -588.06076 | E17: =-Assumptions!H63 -> -600.26565 | F17: =-Assumptions!I63 -> -640.3821 | G17: =-Assumptions!J63 -> -710.89875 | H17: =-Assumptions!K63 -> -778.80989
B18: Acquisitions | D18: 0 | E18: 0 | F18: 0 | G18: 0 | H18: 0
B19: Purchases of investments | D19: 0 | E19: 0 | F19: 0 | G19: 0 | H19: 0
B20: Maturities of investments | D20: 0 | E20: 0 | F20: 0 | G20: 0 | H20: 0
B22: CFI | D22: =SUM(D17:D21) -> -588.06076 | E22: =SUM(E17:E21) -> -600.26565 | F22: =SUM(F17:F21) -> -640.3821 | G22: =SUM(G17:G21) -> -710.89875 | H22: =SUM(H17:H21) -> -778.80989
B24: Cash flow from financing activities
B25: Issuance of debt | D25: 0 | E25: 0 | F25: 0 | G25: 0 | H25: 0
B26: Repayment of borrowings | D26: =Assumptions!G91 -> -400 | E26: =Assumptions!H91 -> -400 | F26: =Assumptions!I91 -> -400 | G26: =Assumptions!J91 -> -400 | H26: =Assumptions!K91 -> -400
B27: Share buyback | D27: =-Assumptions!G127 -> -6154.5465 | E27: =-Assumptions!H127 -> -6209.1462 | F27: =-Assumptions!I127 -> -6181.8464 | G27: =-Assumptions!J127 -> -6195.4963 | H27: =-Assumptions!K127 -> -6188.6713
B28: Issuance of common stock | D28: 0 | E28: 0 | F28: 0 | G28: 0 | H28: 0
B30: CFF | D30: =SUM(D26:D29) -> -6554.5465 | E30: =SUM(E26:E29) -> -6609.1462 | F30: =SUM(F26:F29) -> -6581.8464 | G30: =SUM(G26:G29) -> -6595.4963 | H30: =SUM(H26:H29) -> -6588.6713
B32: Net change in cash | D32: =D14+D22+D30 -> 3172.7834 | E32: =E14+E22+E30 -> 4754.0122 | F32: =F14+F22+F30 -> 5886.5728 | G32: =G14+G22+G30 -> 7366.3633 | H32: =H14+H22+H30 -> 8287.3136
B33: Opening cash balance | D33: =C34 -> 7804.733 | E33: =D34 -> 10977.516 | F33: =E34 -> 15731.529 | G33: =F34 -> 21618.101 | H33: =G34 -> 28984.465
B34: Closing Cash balance | C34: =BS!F7 -> 7804.733 | D34: =D32+D33 -> 10977.516 | E34: =E32+E33 -> 15731.529 | F34: =F32+F33 -> 21618.101 | G34: =G32+G33 -> 28984.465 | H34: =H32+H33 -> 37271.778

Sheet Dupont
B3: Return On Equity(ROE)
C4: 2021 | D4: 2022 | E4: 2023 | F4: 2024
B5: Net Profit | C5: ='P&L'!C16 -> 5116.228 | D5: ='P&L'!D16 -> 4491.924 | E5: ='P&L'!E16 -> 5407.99 | F5: ='P&L'!F16 -> 8711.631
B6: Average Shareholders Equity | C6: 13867.388 | D6: 19266.415 | E6: 24776.677 | F6: 32643.751
B7: Return On Equity | C7: =C5/C6 -> 0.36893957 | D7: =D5/D6 -> 0.23314789 | E7: =E5/E6 -> 0.21826938 | F7: =F5/F6 -> 0.26686979
B9: ROE - Dupont Equation
C10: 2021 | D10: 2022 | E10: 2023 | F10: 2024
B11: Net Profit | C11: =C5 -> 5116.228 | D11: =D5 -> 4491.924 | E11: =E5 -> 5407.99 | F11: =F5 -> 8711.631
B12: Revenue | C12: ='P&L'!C5 -> 29697.844 | D12: ='P&L'!D5 -> 31615.55 | E12: ='P&L'!E5 -> 33723.297 | F12: ='P&L'!F5 -> 39000.966
B13: Net Profit Margin(A) | C13: =C11/C12 -> 0.17227607 | D13: =D11/D12 -> 0.14207958 | E13: =E11/E12 -> 0.16036362 | F13: =F11/F12 -> 0.22336962
B15: Revenue | C15: =C12 -> 29697.844 | D15: =D12 -> 31615.55 | E15: =E12 -> 33723.297 | F15: =F12 -> 39000.966
B16: Average Total Assets | C16: 41932.511 | D16: 46589.715 | E16: 48663.38 | F16: 51181.183
B17: Assets turnover ratio(B) | C17: =C15/C16 -> 0.70822956 | D17: =D15/D16 -> 0.67859504 | E17: =E15/E16 -> 0.69299126 | F17: =F15/F16 -> 0.76201767
B19: Average Total Assets | C19: =C16 -> 41932.511 | D19: =D16 -> 46589.715 | E19: =E16 -> 48663.38 | F19: =F16 -> 51181.183
B20: Average Shareholders Equity | C20: =C6 -> 13867.388 | D20: =D6 -> 19266.415 | E20: =E6 -> 24776.677 | F20: =F6 -> 32643.751
B21: Equity Multiplier(C) | C21: =C19/C20 -> 3.023822 | D21: =D19/D20 -> 2.4181829 | E21: =E19/E20 -> 1.9640801 | F21: =F19/F20 -> 1.5678708
B23: Return On Equity(A*B*C) | C23: =C13*C17*C21 -> 0.36893957 | D23: =D13*D17*D21 -> 0.23314789 | E23: =E13*E17*E21 -> 0.21826938 | F23: =F13*F17*F21 -> 0.26686979
B26: Return on Asset
C27: =C4 -> 2021 | D27: =D4 -> 2022 | E27: =E4 -> 2023 | F27: =F4 -> 2024
B28: Net Profit | C28: =C5 -> 5116.228 | D28: =D5 -> 4491.924 | E28: =E5 -> 5407.99 | F28: =F5 -> 8711.631
B29: =B16 -> Average Total Assets | C29: =C16 -> 41932.511 | D29: =D16 -> 46589.715 | E29: =E16 -> 48663.38 | F29: =F16 -> 51181.183
B30: Return on Asset | C30: =C28/C29 -> 0.12201101 | D30: =D28/D29 -> 0.096414497 | E30: =E28/E29 -> 0.11113059 | F30: =F28/F29 -> 0.1702116
B32: ROA - Dupont Equation
C33: =C27 -> 2021 | D33: =D27 -> 2022 | E33: =E27 -> 2023 | F33: =F27 -> 2024
B34: =B28 -> Net Profit | C34: =C28 -> 5116.228 | D34: =D28 -> 4491.924 | E34: =E28 -> 5407.99 | F34: =F28 -> 8711.631
B35: Revenue | C35: =C12 -> 29697.844 | D35: =D12 -> 31615.55 | E35: =E12 -> 33723.297 | F35: =F12 -> 39000.966
B36: Net Profit Margin (A) | C36: =C34/C35 -> 0.17227607 | D36: =D34/D35 -> 0.14207958 | E36: =E34/E35 -> 0.16036362 | F36: =F34/F35 -> 0.22336962
B38: Revenue | C38: =C35 -> 29697.844 | D38: =D35 -> 31615.55 | E38: =E35 -> 33723.297 | F38: =F35 -> 39000.966
B39: Average Total Asset | C39: =C19 -> 41932.511 | D39: =D19 -> 46589.715 | E39: =E19 -> 48663.38 | F39: =F19 -> 51181.183
B40: Asset Turnover Ratio (B) | C40: =C38/C39 -> 0.70822956 | D40: =D38/D39 -> 0.67859504 | E40: =E38/E39 -> 0.69299126 | F40: =F38/F39 -> 0.76201767
B42: Return on Asset (A*B) | C42: =C40*C36 -> 0.12201101 | D42: =D40*D36 -> 0.096414497 | E42: =E40*E36 -> 0.11113059 | F42: =F40*F36 -> 0.1702116

Sheet Assumptions
B3: Assumptions & Schedules | C3: 2021 | D3: =C3+1 -> 2022 | E3: =D3+1 -> 2023 | F3: =E3+1 -> 2024 | G3: =F3+1 -> 2025 | H3: =G3+1 -> 2026 | I3: =H3+1 -> 2027 | J3: =I3+1 -> 2028 | K3: =J3+1 -> 2029
B4: Year weight | C4: 1 | D4: =C4+1 -> 2 | E4: =D4+1 -> 3 | F4: =E4+1 -> 4 | G4: =F4+1 -> 5 | H4: =G4+1 -> 6 | I4: =H4+1 -> 7 | J4: =I4+1 -> 8 | K4: =J4+1 -> 9
B5: Revenue | C5: US and Canada
B6: Revenues | C6: 12972.1 | D6: 14084.643 | E6: 14873.783 | F6: 17359.369 | G6: =G25*G9 -> 20001.438 | H6: =H25*H9 -> 22453.049 | I6: =I25*I9 -> 24433.007 | J6: =J25*J9 -> 26413.105 | K6: =K25*K9 -> 28512.988
B7: Paid net membership additions | C7: 1279 | D7: -919 | E7: 5832 | F7: 9497 | G7: To be forecasted | H7: To be forecasted | I7: To be forecasted | J7: To be forecasted | K7: To be forecasted
B8: Paid memberships at end of period | C8: 75215 | D8: 74296 | E8: 80128 | F8: 89625 | G8: To be forecasted | H8: To be forecasted | I8: To be forecasted | J8: To be forecasted | K8: To be forecasted
C9: =C6/C25 -> 0.43950134 | D9: =D6/D25 -> 0.44755987 | E9: =E6/E25 -> 0.44213973 | F9: =F6/F25 -> 0.445101 | G9: =AVERAGE(C9:F9) -> 0.44357549 | H9: =AVERAGE(D9:G9) -> 0.44459402 | I9: =AVERAGE(E9:H9) -> 0.44385256 | J9: =AVERAGE(F9:I9) -> 0.44428077 | K9: =AVERAGE(G9:J9) -> 0.44407571
C10: EMEA
B11: Revenues | C11: 9699.819 | D11: 9745.015 | E11: 10556.487 | F11: 12387.035 | G11: =G25*G14 -> 14313.231 | H11: =H25*H14 -> 15889.315 | I11: =I25*I14 -> 17387.658 | J11: =J25*J14 -> 18809.328 | K11: =K25*K14 -> 20294.383
B12: Paid net membership additions | C12: 7338 | D12: 2693 | E12: 12084 | F12: 12320 | G12: To be forecasted | H12: To be forecasted | I12: To be forecasted | J12: To be forecasted | K12: To be forecasted
B13: Paid memberships at end of period | C13: 74036 | D13: 76729 | E13: 88813 | F13: 101133 | G13: To be forecasted | H13: To be forecasted | I13: To be forecasted | J13: To be forecasted | K13: To be forecasted
C14: =C11/C25 -> 0.3286348 | D14: =D11/D25 -> 0.30966193 | E14: =E11/E25 -> 0.31380331 | F14: =F11/F25 -> 0.31760842 | G14: =AVERAGE(C14:F14) -> 0.31742711 | H14: =AVERAGE(D14:G14) -> 0.31462519 | I14: =AVERAGE(E14:H14) -> 0.31586601 | J14: =AVERAGE(F14:I14) -> 0.31638168 | K14: =AVERAGE(G14:J14) -> 0.316075
C15: Latin America
B16: Revenues | C16: 3576.976 | D16: 4069.973 | E16: 4446.461 | F16: 4839.816 | G16: =G25*G19 -> 5712.9648 | H16: =H25*H19 -> 6468.0584 | I16: =I25*I19 -> 7032.9139 | J16: =J25*J19 -> 7529.9224 | K16: =K25*K19 -> 8173.4417
B17: Paid net membership additions | C17: 2424 | D17: 1738 | E17: 4298 | F17: 7330 | G17: To be forecasted | H17: To be forecasted | I17: To be forecasted | J17: To be forecasted | K17: To be forecasted
B18: Paid memberships at end of period | C18: 39961 | D18: 41699 | E18: 45997 | F18: 53327 | G18: To be forecasted | H18: To be forecasted | I18: To be forecasted | J18: To be forecasted | K18: To be forecasted
C19: =C16/C25 -> 0.12118976 | D19: =D16/D25 -> 0.12932927 | E19: =E16/E25 -> 0.13217599 | F19: =F16/F25 -> 0.12409477 | G19: =AVERAGE(C19:F19) -> 0.12669745 | H19: =AVERAGE(D19:G19) -> 0.12807437 | I19: =AVERAGE(E19:H19) -> 0.12776065 | J19: =AVERAGE(F19:I19) -> 0.12665681 | K19: =AVERAGE(G19:J19) -> 0.12729732
C20: Asia Pacific
B21: Revenues | C21: 3266.601 | D21: 3570.221 | E21: 3763.727 | F21: 4414.746 | G21: =G25*G26 -> 7041.5168 | H21: =H25*H26 -> 6060.2835 | I21: =I25*I26 -> 4954.2818 | J21: =J25*J26 -> 4756.1105 | K21: =K25*K26 -> 5136.5994
B22: Paid net membership additions | C22: 7140 | D22: 5391 | E22: 7315 | F22: 12203 | G22: To be forecasted | H22: To be forecasted | I22: To be forecasted | J22: To be forecasted | K22: To be forecasted
B23: Paid memberships at end of period | C23: 32632 | D23: 38023 | E23: 45338 | F23: 57541 | G23: To be forecasted | H23: To be forecasted | I23: To be forecasted | J23: To be forecasted | K23: To be forecasted
C24: =C21/C25 -> 0.1106741 | D24: =D21/D25 -> 0.11344893 | E24: =E21/E25 -> 0.11188097 | F24: =F21/F25 -> 0.11319581 | G24: =AVERAGE(C24:F24) -> 0.11229995 | H24: =AVERAGE(D24:G24) -> 0.11270642 | I24: =AVERAGE(E24:H24) -> 0.11252079 | J24: =AVERAGE(F24:I24) -> 0.11268074 | K24: =AVERAGE(G24:J24) -> 0.11255197
B25: Total revenue from subscription | C25: =C6+C11+C16+C21 -> 29515.496 | D25: =D6+D11+D16+D21 -> 31469.852 | E25: =E6+E11+E16+E21 -> 33640.458 | F25: =F6+F11+F16+F21 -> 39000.966 | G25: 45091.395 | H25: =G25*(1+H26) -> 50502.363 | I25: =H25*(1+I26) -> 55047.575 | J25: =I25*(1+J26) -> 59451.381 | K25: =J25*(1+K26) -> 64207.492
B26: Revenue growth | D26: =D25/C25-1 -> 0.066214574 | E26: =E25/D25-1 -> 0.068974141 | F26: =F25/E25-1 -> 0.15934706 | G26: =G25/F25-1 -> 0.15616099 | H26: 0.12 | I26: 0.09 | J26: 0.08 | K26: 0.08
B27: Total membership additions/losses | C27: =C7+C12+C17+C22 -> 18181 | D27: =D7+D12+D17+D22 -> 8903 | E27: =E7+E12+E17+E22 -> 29529 | F27: =F7+F12+F17+F22 -> 41350
B28: Total paid memberships | C28: =C8+C13+C18+C23 -> 221844 | D28: =D8+D13+D18+D23 -> 230747 | E28: =E8+E13+E18+E23 -> 260276 | F28: =F8+F13+F18+F23 -> 301626
B29: Memberships growth | D29: =D28/C28-1 -> 0.040131804 | E29: =E28/D28-1 -> 0.12797133 | F29: =F28/E28-1 -> 0.15886982
B32: SG&A
B33: ='P&L'!B7 -> Sales and marketing | C33: ='P&L'!C7 -> 2545.146 | D33: ='P&L'!D7 -> 2530.502 | E33: ='P&L'!E7 -> 2657.883 | F33: ='P&L'!F7 -> 2917.554 | G33: 3017.4712 | H33: =G33*(1+H34) -> 3251.2504 | I33: =H33*(1+I34) -> 3497.4483 | J33: =I33*(1+J34) -> 3759.0112 | K33: =J33*(1+K34) -> 4036.9617
B34: as % of sales | C34: =C33/C25 -> 0.08623084 | D34: =D33/D25 -> 0.080410356 | E34: =E33/E25 -> 0.079008526 | F34: =F33/F25 -> 0.074807224 | G34: =G33/G25 -> 0.066919003 | H34: =AVERAGE(C34:G34) -> 0.07747519 | I34: =AVERAGE(D34:H34) -> 0.07572406 | J34: =AVERAGE(E34:I34) -> 0.074786801 | K34: =AVERAGE(F34:J34) -> 0.073942455
B35: ='P&L'!B8 -> Technology and development | C35: ='P&L'!C8 -> 2273.885 | D35: ='P&L'!D8 -> 2711.041 | E35: ='P&L'!E8 -> 2675.758 | F35: ='P&L'!F8 -> 2925.295 | G35: 3401.6211 | H35: =G35*(1+H36) -> 3669.1053 | I35: =H35*(1+I36) -> 3958.7925 | J35: =I35*(1+J36) -> 4265.6554 | K35: =J35*(1+K36) -> 4594.5765
B36: as % of sales | C36: =C35/C25 -> 0.077040379 | D36: =D35/D25 -> 0.086147243 | E36: =E35/E25 -> 0.07953988 | F36: =F35/F25 -> 0.075005706 | G36: =G35/G25 -> 0.075438365 | H36: =AVERAGE(C36:G36) -> 0.078634315 | I36: =AVERAGE(D36:H36) -> 0.078953102 | J36: =AVERAGE(E36:I36) -> 0.077514274 | K36: =AVERAGE(F36:J36) -> 0.077109152
B37: ='P&L'!B9 -> General and administrative | C37: ='P&L'!C9 -> 1351.621 | D37: ='P&L'!D9 -> 1572.891 | E37: ='P&L'!E9 -> 1720.285 | F37: ='P&L'!F9 -> 1702.039 | G37: 1803.7232 | H37: =G37*(1+H38) -> 1886.8944 | I37: =H37*(1+I38) -> 1974.0205 | J37: =I37*(1+J38) -> 2063.6667 | K37: =J37*(1+K38) -> 2155.0213
B38: as % of sales | C38: =C37/C25 -> 0.045793606 | D38: =D37/D25 -> 0.049980883 | E38: =E37/E25 -> 0.051137383 | F38: =F37/F25 -> 0.043640945 | G38: =G37/G25 -> 0.040001495 | H38: =AVERAGE(C38:G38) -> 0.046110862 | I38: =AVERAGE(D38:H38) -> 0.046174314 | J38: =AVERAGE(E38:I38) -> 0.045413 | K38: =AVERAGE(F38:J38) -> 0.044268123
B40: Tax expense
B41: ='P&L'!B14 -> Income before income taxes | C41: ='P&L'!C14 -> 5840.103 | D41: ='P&L'!D14 -> 5263.929 | E41: ='P&L'!E14 -> 6205.405 | F41: ='P&L'!F14 -> 9965.657 | G41: ='P&L'!G14 -> 14120.573 | H41: ='P&L'!H14 -> 17281.171 | I41: ='P&L'!I14 -> 18769.844 | ... K41: ='P&L'!K14 -> 21538.813
B42: Tax expense | C42: ='P&L'!C15 -> -723.875 | D42: ='P&L'!D15 -> -772.005 | E42: ='P&L'!E15 -> -797.415 | F42: ='P&L'!F15 -> -1254.026 | G42: =-G41*G43 -> -1776.8588 | H42: =-H41*H43 -> -2174.5719 | I42: =-I41*I43 -> -2361.8987 | J42: =-J41*J43 -> -2480.9612 | K42: =-K41*K43 -> -2710.3312
B43: Tax rate | C43: =-C42/C41 -> 0.12394901 | D43: =-D42/D41 -> 0.14665946 | E43: =-E42/E41 -> 0.1285033 | F43: =-F42/F41 -> 0.12583475 | G43: =F43 -> 0.12583475 | H43: =G43 -> 0.12583475 | I43: =H43 -> 0.12583475 | J43: =I43 -> 0.12583475 | K43: =J43 -> 0.12583475
B45: Cost of Revenues
B46: COGS | C46: 4893.904 | D46: 4805.471 | E46: 5160.984 | F46: 5408.033 | G46: ='P&L'!G5*Assumptions!G47 -> 6859.4175 | H46: ='P&L'!H5*Assumptions!H47 -> 7522.615 | I46: ='P&L'!I5*Assumptions!I47 -> 8157.7954 | J46: ='P&L'!J5*Assumptions!J47 -> 8738.4269 | K46: ='P&L'!K5*Assumptions!K47 -> 9571.0581
...

Sheet CCA
B3: Comparable Company Analysis
B4: Market Data | J4: Financials(TTM) | N4: Valuation
B5: Company | C5: Ticker | D5: CMP | E5: Shares O/S | F5: Equity value | G5: Net Debt | H5: Enterprise value | J5: Revenue | K5: EBITDA | L5: Net Income | N5: EV/Revenue | O5: EV/EBITDA | P5: P/E
B6: Netflix,Inc | C6: NFLX | D6: 90.53 | E6: 4.24 | F6: 384.02 | G6: 77.78071 | H6: 389.16 | J6: 43.378787 | K6: 28.970173 | L6: 10.43 | N6: =H6/J6 -> 8.9712052 | O6: =H6/K6 -> 13.433127 | P6: =F6/L6 -> 36.818792
B7: Walt Disney Company | C7: DIS | D7: 114.17 | E7: 1.79 | F7: 203.83 | G7: 36.331 | H7: 243.01 | J7: 94.42 | K7: 19.141 | L7: 12.4 | N7: =H7/J7 -> 2.5737132 | O7: =H7/K7 -> 12.695784 | P7: =F7/L7 -> 16.437903
B8: Warner bros Discovery | C8: WBD | D8: 28.32 | E8: 2.48 | F8: 70.291 | G8: 34.193 | H8: 99.45 | J8: 37.86 | K8: 21.854 | L8: 0.489 | N8: =H8/J8 -> 2.6267829 | O8: =H8/K8 -> 4.5506543 | P8: =F8/L8 -> 143.74438
B10: High | N10: =MAX(N7:N8) -> 2.6267829 | O10: =MAX(O7:O8) -> 12.695784 | P10: =MAX(P7:P8) -> 143.74438
B11: 75th Percentile | N11: =QUARTILE(N7:N8,3) -> 2.6135155 | O11: =QUARTILE(O7:O8,3) -> 10.659502 | P11: =QUARTILE(P7:P8,3) -> 111.91776
B12: Average | N12: =AVERAGE(N7:N8) -> 2.600248 | O12: =AVERAGE(O7:O8) -> 8.6232191 | P12: =AVERAGE(P7:P8) -> 80.09114
B13: Median | N13: =MEDIAN(N7:N8) -> 2.600248 | O13: =MEDIAN(O7:O8) -> 8.6232191 | P13: =MEDIAN(P7:P8) -> 80.09114
B14: 25th percentile | N14: =QUARTILE(N7:N8,1) -> 2.5869806 | O14: =QUARTILE(O7:O8,1) -> 6.5869367 | P14: =QUARTILE(P7:P8,1) -> 48.264521
B15: Low | N15: =MIN(N7:N8) -> 2.5737132 | O15: =MIN(O7:O8) -> 4.5506543 | P15: =MIN(P7:P8) -> 16.437903
B17: NETFLIX,inc Valuation | N17: EV/Revenue | O17: EV/EBITDA | P17: P/E
B18: Implied Enterprise Value | N18: =N13*J6 -> 112.79561 | O18: =O13*K6 -> 249.81615
B19: Net Debt | N19: =$G$6 -> 77.78071 | O19: =$G$6 -> 77.78071 | P19: =$G$6 -> 77.78071
B20: Implied Market Value | N20: =N18-N19 -> 35.014896 | O20: =O18-O19 -> 172.03544 | P20: =P13*L6 -> 835.35059
B21: Shares O/S | N21: =$E$6 -> 4.24 | O21: =$E$6 -> 4.24 | P21: =$E$6 -> 4.24
B22: Implied Value per Share | N22: =N20/N21 -> 8.2582302 | O22: =O20/O21 -> 40.574396 | P22: =P20/P21 -> 197.01665
B24: #Figures for CCA in Billion Dollars except per share value

Sheet DCF
C4: Discounted Cash Flow
K5: WACC | L5: =WACC!H25 -> 0.081171254
C6: Year | D6: =CFS!D3 -> 2025 | E6: =CFS!E3 -> 2026 | F6: =CFS!F3 -> 2027 | G6: =CFS!G3 -> 2028 | H6: =CFS!H3 -> 2029 | K6: LTGR | L6: 0.03
C7: Year Weight | D7: 1 | E7: =D7+1 -> 2 | F7: =E7+1 -> 3 | G7: =F7+1 -> 4 | H7: =G7+1 -> 5 | K7: Tax | L7: 0.1258
D10: Free Cash Flow To Firm | K10: Perpetuity Growth Model
C11: EBIT | D11: ='P&L'!G10 -> 14591.926 | E11: ='P&L'!H10 -> 17732.143 | F11: ='P&L'!I10 -> 19203.192 | G11: ='P&L'!J10 -> 20128.655 | H11: ='P&L'!K10 -> 21932.931 | K11: Terminal Value | L11: =H17*(1+L6)/(L5-L6) -> 306381.19
C12: Tax | D12: =D11*$L$7 -> 1835.6642 | E12: =E11*$L$7 -> 2230.7035 | F12: =F11*$L$7 -> 2415.7615 | G12: =G11*$L$7 -> 2532.1848 | H12: =H11*$L$7 -> 2759.1627 | K12: PV of TV | L12: =L11/(1+L5)^H7 -> 207390.88
C13: NOPAT | D13: =D11-D12 -> 12756.261 | E13: =E11-E12 -> 15501.439 | F13: =F11-F12 -> 16787.43 | G13: =G11-G12 -> 17596.47 | H13: =H11-H12 -> 19173.768
C14: D&A | D14: =Assumptions!G56-Assumptions!G65 -> 15417.237 | E14: =Assumptions!H56-Assumptions!H65 -> 16440.355 | F14: =Assumptions!I56-Assumptions!I65 -> 18256.327 | G14: =Assumptions!J56-Assumptions!J65 -> 20495.966 | H14: =Assumptions!K56-Assumptions!K65 -> 21916.943 | K14: Enterprise value | L14: =SUM(L12,D18:H18) -> 257780.04
C15: Capex | D15: =-CFS!D7-CFS!D17 -> 18088.061 | E15: =-CFS!E7-CFS!E17 -> 20403.358 | F15: =-CFS!F7-CFS!F17 -> 22589.733 | G15: =-CFS!G7-CFS!G17 -> 24074.439 | H15: =-CFS!H7-CFS!H17 -> 26115.984 | K15: -Debt | L15: =BS!F22+BS!F25 -> 15582.804
C16: Change in WC | D16: =Assumptions!G114 -> -54.440271 | E16: =Assumptions!H114 -> -219.56186 | F16: =Assumptions!I114 -> -393.87996 | G16: =Assumptions!J114 -> -305.26814 | H16: =Assumptions!K114 -> -246.544 | K16: -NCI | L16: 0
C17: FCF | D17: =D13+D14-D15-D16 -> 10139.878 | E17: =E13+E14-E15-E16 -> 11757.998 | F17: =F13+F14-F15-F16 -> 12847.904 | G17: =G13+G14-G15-G16 -> 14323.266 | H17: =H13+H14-H15-H16 -> 15221.271 | K17: +Cash | L17: =BS!F7 -> 7804.733
C18: PV of FCF | D18: =D17/(1+$L$5)^D7 -> 9378.6044 | E18: =E17/(1+$L$5)^E7 -> 10058.759 | F18: =F17/(1+$L$5)^F7 -> 10165.97 | G18: =G17/(1+$L$5)^G7 -> 10482.481 | H18: =H17/(1+$L$5)^H7 -> 10303.351 | K18: +Investments | L18: =BS!F8 -> 1779.006
K19: Equity Value | L19: =L14-L15-L16+L17+L18 -> 251780.98
E20: Sensitivity Analysis | K20: No.of Shares | L20: ='P&L'!F22 -> 4392.61
E21: WACC | K21: Intrinsic value | L21: =L19/L20 -> 57.319219
C22: LTGR | D22: =L21 -> 57.319219 | E22: 0.0612 | F22: 0.0712 | G22: 0.0812 | H22: 0.0912 | I22: 0.1012
D23: 0.025 | E23: 83.684922 | F23: 64.942531 | G23: 52.879273 | H23: 44.467998 | I23: 38.270628 | K23: CMP | L23: $90.53
D24: 0.03 | E24: 95.781044 | F24: 71.855694 | G24: 57.28551 | H24: 47.484277 | I24: 40.442321 | K24: as on 9th Jan,2026
D25: 0.035 | E25: 112.49401 | F25: 80.678572 | G25: 62.645478 | H25: 51.03726 | I25: 42.942065 | K25: Valuation | L25: {=IF(L21>Table_8__2[Column1],"Undervalued","Overvalued")} -> Overvalued
D26: 0.04 | E26: 137.09044 | F26: 92.329295 | G26: 69.306409 | H26: 55.284185 | I26: 45.850264
D27: 0.045 | E27: 176.86986 | F27: 108.42686 | G27: 77.807377 | H27: 60.450357 | I27: 49.275935
D30: Free Cash Flow To Equity | K30: Perpetuity Growth Model
C31: EBIT | D31: ='P&L'!G10 -> 14591.926 | E31: ='P&L'!H10 -> 17732.143 | F31: ='P&L'!I10 -> 19203.192 | G31: ='P&L'!J10 -> 20128.655 | H31: ='P&L'!K10 -> 21932.931 | K31: Terminal Value | L31: =H38*(1+L6)/(L5-L6) -> 314432.58
C32: Tax | D32: =D31*$L$7 -> 1835.6642 | E32: =E31*$L$7 -> 2230.7035 | F32: =F31*$L$7 -> 2415.7615 | G32: =G31*$L$7 -> 2532.1848 | H32: =H31*$L$7 -> 2759.1627 | K32: PV of TV | L32: =L31/(1+L5)^H7 -> 212840.9
C33: NOPAT | D33: =D31-D32 -> 12756.261 | E33: =E31-E32 -> 15501.439 | F33: =F31-F32 -> 16787.43 | G33: =G31-G32 -> 17596.47 | H33: =H31-H32 -> 19173.768
C34: D&A | D34: =D14 -> 15417.237 | E34: =E14 -> 16440.355 | F34: =F14 -> 18256.327 | G34: =G14 -> 20495.966 | H34: =H14 -> 21916.943 | K34: Equity value | L34: =SUM(L32,D39:H39) -> 264822.23
C35: Capex | D35: =D15 -> 18088.061 | E35: =E15 -> 20403.358 | F35: =F15 -> 22589.733 | G35: =G15 -> 24074.439 | H35: =H15 -> 26115.984
C36: Change in WC | D36: =D16 -> -54.440271 | E36: =E16 -> -219.56186 | F36: =F16 -> -393.87996 | G36: =G16 -> -305.26814 | H36: =H16 -> -246.544 | K36: No.of Shares | L36: =L20 -> 4392.61
C37: Net borrowing | D37: =-CFS!D26 -> 400 | E37: =-CFS!E26 -> 400 | F37: =-CFS!F26 -> 400 | G37: =-CFS!G26 -> 400 | H37: =-CFS!H26 -> 400 | K37: Intrinsic value | L37: =L34/L36 -> 60.288128
C38: FCF | D38: =D33+D34-D35-D36+D37 -> 10539.878 | E38: =E33+E34-E35-E36+E37 -> 12157.998 | F38: =F33+F34-F35-F36+F37 -> 13247.904 | G38: =G33+G34-G35-G36+G37 -> 14723.266 | H38: =H33+H34-H35-H36+H37 -> 15621.271
C39: PV of FCF | D39: =D38/(1+$L$5)^D7 -> 9748.5736 | E39: =E38/(1+$L$5)^E7 -> 10400.952 | F39: =F38/(1+$L$5)^F7 -> 10482.472 | G39: =G38/(1+$L$5)^G7 -> 10775.221 | H39: =H38/(1+$L$5)^H7 -> 10574.113 | K39: CMP | L39: $90.53
K40: =K24 -> as on 9th Jan,2026
E41: Sensitivity Analysis | K41: Valuation | L41: {=IF(L37>Table_8[CMP],"Undervalued","Overvalued")} -> Overvalued
E42: WACC
C43: LTGR | D43: =L37 -> 60.288128 | E43: 0.0612 | F43: 0.0712 | G43: 0.0812 | H43: 0.0912 | I43: 0.1012
D44: 0.025 | E44: 87.348849 | F44: 68.112831 | G44: 55.731501 | H44: 47.098157 | I44: 40.736928
D45: 0.03 | E45: 99.762845 | F45: 75.207666 | G45: 60.25353 | H45: 50.193701 | I45: 42.965691
D46: 0.035 | E46: 116.91501 | F46: 84.2624 | G46: 65.754353 | H46: 53.840053 | I46: 45.531126
D47: 0.04 | E47: 142.15781 | F47: 96.219292 | G47: 72.590327 | H47: 58.198583 | I47: 48.515749
...

Sheet WACC
B2: Weighted Average Cost of Capital
B4: All figures are in million dollars stated otherwise
B6: Cost of Debt | G6: Cost of Equity
B8: Pre-tax cost of debt | E8: =-'P&L'!F12/(BS!F25+BS!F22) -> 0.04612347 | G8: Risk free rate | J8: 0.04172
B9: Tax | E9: =-'P&L'!F15/'P&L'!F14 -> 0.12583475 | G9: Equity risk premium | J9: 0.0446
B10: Post- tax cost of debt | E10: =E8*(1-E9) -> 0.040319535 | G10: Beta | J10: ='Regression Beta'!K15 -> 0.92111599
G11: Cost of Equity | J11: =J8+(J9*J10) -> 0.082801773
B12: Netflix Capital Structure
B13: Equity | C13: ='P&L'!G22*90.61 -> 390418.12
B14: Debt | C14: =BS!F22+BS!F25 -> 15582.804
B15: Total Capital | C15: =C13+C14 -> 406000.92
D17: Weighted Average Cost of Capital
D19: Cost of Equity | H19: =J11 -> 0.082801773
D20: Equity Weight | H20: =C13/C15 -> 0.9616188
D22: Cost of Debt | H22: =E10 -> 0.040319535
D23: Debt Weight | H23: =C14/C15 -> 0.038381204
D25: WACC | H25: =(H19*H20)+(H22*H23) -> 0.081171254

Sheet Regression Beta
B3: Regression Beta
B4: Weekly Historical Price | C4: 45292 | D4: 46022
C6: NASDAQ | G6: NETFLIX
B7: Date | C7: Price | D7: Change % | G7: Price | H7: Change % | J7: Regression Beta Methodology and Results
B8: 46019 | C8: 23241.99 | D8: =C8/C9-1 -> -0.014881893 | G8: 93.76 | H8: =G8/G9-1 -> -0.0075156134 | J8: Raw BETA | K8: =SLOPE(H8:H110,$D$8:$D$110) -> 0.89482133 | M8: Parameter | N8: Value
B9: 46012 | C9: 23593.1 | D9: =C9/C10-1 -> 0.012248355 | G9: 94.47 | H9: =G9/G10-1 -> 0.00084754741 | J9: NETFLIX Beta Drifting | M9: Data Period | N9: January 1, 2024 – December 31, 2025
B10: 46005 | C10: 23307.62 | D10: =C10/C11-1 -> 0.0048479921 | G10: 94.39 | H10: =G10/G11-1 -> -0.0084042441 | J10: Levered Raw Beta | K10: =K8 -> 0.89482133 | M10: Frequency | N10: Weekly
B11: 45998 | C11: 23195.17 | D11: =C11/C12-1 -> -0.01624217 | G11: 95.19 | H11: =G11/G12-1 -> -0.05037909 | J11: Raw Beta Weight | K11: 0.75 | M11: Market Index | N11: NASDAQ
B12: 45991 | C12: 23578.13 | D12: =C12/C13-1 -> 0.0090919635 | G12: 100.24 | H12: =G12/G13-1 -> -0.068228295 | M12: Raw Regression Beta (Levered) | N12: 0.89
B13: 45984 | C13: 23365.69 | D13: =C13/C14-1 -> 0.049055182 | G13: 107.58 | H13: =G13/G14-1 -> 0.031348864 | J13: Market Beta | K13: 1 | M13: R-squared | N13: 0.28
B14: 45977 | C14: 22273.08 | D14: =C14/C15-1 -> -0.027401477 | G14: 104.31 | H14: =G14/G15-1 -> -0.062129113 | J14: Market Beta Weight | K14: 0.25 | M14: Blume Adjustment Formula | N14: 0.75 × Raw Beta + 0.25 × 1.0
B15: 45970 | C15: 22900.59 | D15: =C15/C16-1 -> -0.0045186733 | G15: 111.22 | H15: =G15/G16-1 -> 0.0077013681 | J15: Adjusted Beta | K15: =(K10*K11)+(K13*K14) -> 0.92111599 | M15: Adjusted Beta (Blume Formula) | N15: 0.92
B16: 45963 | C16: 23004.54 | D16: =C16/C17-1 -> -0.030365488 | G16: 110.37 | H16: =G16/G17-1 -> -0.013584771 | M16: Interpretation | N16: Netflix moves 0.92% for every 1% move in the market.
B17: 45956 | C17: 23724.96 | D17: =C17/C18-1 -> 0.022412968 | G17: 111.89 | H17: =G17/G18-1 -> 0.022106513
B18: 45949 | C18: 23204.87 | D18: =C18/C19-1 -> 0.02314377 | G18: 109.47 | H18: =G18/G19-1 -> -0.087293647
B19: 45942 | C19: 22679.97 | D19: =C19/C20-1 -> 0.021416447 | G19: 119.94 | H19: =G19/G20-1 -> -0.016965822
B20: 45935 | C20: 22204.43 | D20: =C20/C21-1 -> -0.025288284 | G20: 122.01 | H20: =G20/G21-1 -> 0.057920749
B21: 45928 | C21: 22780.51 | D21: =C21/C22-1 -> 0.013184446 | G21: 115.33 | H21: =G21/G22-1 -> -0.047331902
B22: 45921 | C22: 22484.07 | D22: =C22/C23-1 -> -0.0065134936 | G22: 121.06 | H22: =G22/G23-1 -> -0.013365933
B23: 45914 | C23: 22631.48 | D23: =C23/C24-1 -> 0.022147951 | G23: 122.7 | H23: =G23/G24-1 -> 0.032480646
B24: 45907 | C24: 22141.1 | D24: =C24/C25-1 -> 0.020308852 | G24: 118.84 | H24: =G24/G25-1 -> -0.044540923
B25: 45900 | C25: 21700.39 | D25: =C25/C26-1 -> 0.0114115 | G25: 124.38 | H25: =G25/G26-1 -> 0.02946532
B26: 45893 | C26: 21455.55 | D26: =C26/C27-1 -> -0.0019068185 | G26: 120.82 | H26: =G26/G27-1 -> 0.0029885439
B27: 45886 | C27: 21496.54 | D27: =C27/C28-1 -> -0.0058474826 | G27: 120.46 | H27: =G27/G28-1 -> -0.02768585
B28: 45879 | C28: 21622.98 | D28: =C28/C29-1 -> 0.0080633957 | G28: 123.89 | H28: =G28/G29-1 -> 0.022532189
... B110: 45305 | C110: 15310.97 | D110: =C110/C111-1 -> 0.022588354 | G110: 48.29 | H110: =G110/G111-1 -> -0.018894758
B111: 45298 | C111: 14972.76 | G111: 49.22

Sheet Ratio Analysis
B4: Year | C4: 2021 | D4: 2022 | E4: 2023 | F4: 2024 | G4: 2025 | H4: 2026 | I4: 2027 | J4: 2028 | K4: 2029 | L4: Trend | M4: Mean | N4: Median
B6: Sales growth | D6: ='P&L'!D5/'P&L'!C5-1 -> 0.064573913 | E6: ='P&L'!E5/'P&L'!D5-1 -> 0.066668048 | F6: ='P&L'!F5/'P&L'!E5-1 -> 0.1564992 | G6: ='P&L'!G5/'P&L'!F5-1 -> 0.15616099 | H6: ='P&L'!H5/'P&L'!G5-1 -> 0.12 | I6: ='P&L'!I5/'P&L'!H5-1 -> 0.09 | J6: ='P&L'!J5/'P&L'!I5-1 -> 0.08 | K6: ='P&L'!K5/'P&L'!J5-1 -> 0.08 | M6: =IFERROR(AVERAGE(C6:K6),0) -> 0.10173777 | N6: =IFERROR(MEDIAN(C6:K6),0) -> 0.085
B7: EBITDA growth | D7: =('P&L'!D10+Assumptions!D48+Assumptions!D49)/('P&L'!C10+Assumptions!C48+Assumptions!C49)-1 -> 0.073114149 | E7: =('P&L'!E10+Assumptions!E48+Assumptions!E49)/('P&L'!D10+Assumptions!D48+Assumptions!D49)-1 -> 0.075653574 | F7: =('P&L'!F10+Assumptions!F48+Assumptions!F49)/('P&L'!E10+Assumptions!E48+Assumptions!E49)-1 -> 0.21106455 | G7: =('P&L'!G10+Assumptions!G48+Assumptions!G49)/('P&L'!F10+Assumptions!F48+Assumptions!F49)-1 -> 0.15206966 | H7: =('P&L'!H10+Assumptions!H48+Assumptions!H49)/('P&L'!G10+Assumptions!G48+Assumptions!G49)-1 -> 0.13873548 | I7: =('P&L'!I10+Assumptions!I48+Assumptions!I49)/('P&L'!H10+Assumptions!H48+Assumptions!H49)-1 -> 0.096189079 | J7: =('P&L'!J10+Assumptions!J48+Assumptions!J49)/('P&L'!I10+Assumptions!I48+Assumptions!I49)-1 -> 0.084493944 | K7: =('P&L'!K10+Assumptions!K48+Assumptions!K49)/('P&L'!J10+Assumptions!J48+Assumptions!J49)-1 -> 0.079391584 | M7: =IFERROR(AVERAGE(C7:K7),0) -> 0.113839 | N7: =IFERROR(MEDIAN(C7:K7),0) -> 0.090341512
B8: EBIT growth | D8: ='P&L'!D14/'P&L'!C14-1 -> -0.098658191 | E8: ='P&L'!E14/'P&L'!D14-1 -> 0.17885424 | F8: ='P&L'!F14/'P&L'!E14-1 -> 0.60596399 | G8: ='P&L'!G14/'P&L'!F14-1 -> 0.4169234 | H8: ='P&L'!H14/'P&L'!G14-1 -> 0.22382936 | I8: ='P&L'!I14/'P&L'!H14-1 -> 0.086144218 | J8: ='P&L'!J14/'P&L'!I14-1 -> 0.050409626 | K8: ='P&L'!K14/'P&L'!J14-1 -> 0.092452094 | M8: =IFERROR(AVERAGE(C8:K8),0) -> 0.19448984 | N8: =IFERROR(MEDIAN(C8:K8),0) -> 0.13565316
B9: Net profit growth | D9: ='P&L'!D16/'P&L'!C16-1 -> -0.12202427 | E9: ='P&L'!E16/'P&L'!D16-1 -> 0.20393622 | F9: ='P&L'!F16/'P&L'!E16-1 -> 0.61088149 | G9: ='P&L'!G16/'P&L'!F16-1 -> 0.4169234 | H9: ='P&L'!H16/'P&L'!G16-1 -> 0.22382936 | I9: ='P&L'!I16/'P&L'!H16-1 -> 0.086144218 | J9: ='P&L'!J16/'P&L'!I16-1 -> 0.050409626 | K9: ='P&L'!K16/'P&L'!J16-1 -> 0.092452094 | M9: =IFERROR(AVERAGE(C9:K9),0) -> 0.19531902 | N9: =IFERROR(MEDIAN(C9:K9),0) -> 0.14819416
B11: Operating margin | C11: ='P&L'!C10/'P&L'!C5 -> 0.20858447 | D11: ='P&L'!D10/'P&L'!D5 -> 0.17816647 | E11: ='P&L'!E10/'P&L'!E5 -> 0.20620768 | F11: ='P&L'!F10/'P&L'!F5 -> 0.26711169 | G11: ='P&L'!G10/'P&L'!G5 -> 0.32360776 | H11: ='P&L'!H10/'P&L'!H5 -> 0.35111511 | I11: ='P&L'!I10/'P&L'!I5 -> 0.34884718 | J11: ='P&L'!J10/'P&L'!J5 -> 0.33857338 | K11: ='P&L'!K10/'P&L'!K5 -> 0.34159457 | M11: =IFERROR(AVERAGE(C11:K11),0) -> 0.28486759 | N11: =IFERROR(MEDIAN(C11:K11),0) -> 0.32360776
B12: EBITDA margin | C12: =('P&L'!C10+Assumptions!C48+Assumptions!C49)/'P&L'!C5 -> 0.62742898 | D12: =('P&L'!D10+Assumptions!D48+Assumptions!D49)/'P&L'!D5 -> 0.63246235 | E12: =('P&L'!E10+Assumptions!E48+Assumptions!E49)/'P&L'!E5 -> 0.63779016 | F12: =('P&L'!F10+Assumptions!F48+Assumptions!F49)/'P&L'!F5 -> 0.66788205 | G12: =('P&L'!G10+Assumptions!G48+Assumptions!G49)/'P&L'!G5 -> 0.6655186 | H12: =('P&L'!H10+Assumptions!H48+Assumptions!H49)/'P&L'!H5 -> 0.67665146 | I12: =('P&L'!I10+Assumptions!I48+Assumptions!I49)/'P&L'!I5 -> 0.68049353 | J12: =('P&L'!J10+Assumptions!J48+Assumptions!J49)/'P&L'!J5 -> 0.6833251 | K12: =('P&L'!K10+Assumptions!K48+Assumptions!K49)/'P&L'!K5 -> 0.68294015 | M12: =IFERROR(AVERAGE(C12:K12),0) -> 0.66161026 | N12: =IFERROR(MEDIAN(C12:K12),0) -> 0.66788205
B13: EBIT margin | C13: ='P&L'!C10/'P&L'!C5 -> 0.20858447 | D13: ='P&L'!D10/'P&L'!D5 -> 0.17816647 | E13: ='P&L'!E10/'P&L'!E5 -> 0.20620768 | F13: ='P&L'!F10/'P&L'!F5 -> 0.26711169 | G13: ='P&L'!G10/'P&L'!G5 -> 0.32360776 | H13: ='P&L'!H10/'P&L'!H5 -> 0.35111511 | I13: ='P&L'!I10/'P&L'!I5 -> 0.34884718 | J13: ='P&L'!J10/'P&L'!J5 -> 0.33857338 | K13: ='P&L'!K10/'P&L'!K5 -> 0.34159457 | M13: =IFERROR(AVERAGE(C13:K13),0) -> 0.28486759 | N13: =IFERROR(MEDIAN(C13:K13),0) -> 0.32360776
B14: EBT margin | C14: ='P&L'!C14/'P&L'!C5 -> 0.19665074 | D14: ='P&L'!D14/'P&L'!D5 -> 0.1664981 | E14: ='P&L'!E14/'P&L'!E5 -> 0.18400944 | F14: ='P&L'!F14/'P&L'!F5 -> 0.25552334 | G14: ='P&L'!G14/'P&L'!G5 -> 0.31315448 | H14: ='P&L'!H14/'P&L'!H5 -> 0.3421854 | I14: ='P&L'!I14/'P&L'!I5 -> 0.34097495 | J14: ='P&L'!J14/'P&L'!J5 -> 0.33163275 | K14: ='P&L'!K14/'P&L'!K5 -> 0.33545638 | M14: =IFERROR(AVERAGE(C14:K14),0) -> 0.27400951 | N14: =IFERROR(MEDIAN(C14:K14),0) -> 0.31315448
B15: Net Profit Margin | C15: ='P&L'!C16/'P&L'!C5 -> 0.17227607 | D15: ='P&L'!D16/'P&L'!D5 -> 0.14207958 | E15: ='P&L'!E16/'P&L'!E5 -> 0.16036362 | F15: ='P&L'!F16/'P&L'!F5 -> 0.22336962 | G15: ='P&L'!G16/'P&L'!G5 -> 0.27374877 | H15: ='P&L'!H16/'P&L'!H5 -> 0.29912659 | I15: ='P&L'!I16/'P&L'!I5 -> 0.29806845 | J15: ='P&L'!J16/'P&L'!J5 -> 0.28990182 | K15: ='P&L'!K16/'P&L'!K5 -> 0.29324431 | M15: =IFERROR(AVERAGE(C15:K15),0) -> 0.23913098 | N15: =IFERROR(MEDIAN(C15:K15),0) -> 0.27374877
B17: SG&A as % of sales | C17: =SUM('P&L'!C7:C9)/'P&L'!C5 -> 0.20778114 | D17: =SUM('P&L'!D7:D9)/'P&L'!D5 -> 0.21554058 | E17: =SUM('P&L'!E7:E9)/'P&L'!E5 -> 0.20917071 | F17: =SUM('P&L'!F7:F9)/'P&L'!F5 -> 0.19345387 | G17: =SUM('P&L'!G7:G9)/'P&L'!G5 -> 0.18235886 | H17: =SUM('P&L'!H7:H9)/'P&L'!H5 -> 0.17439283 | I17: =SUM('P&L'!I7:I9)/'P&L'!I5 -> 0.17131111 | J17: =SUM('P&L'!J7:J9)/'P&L'!J5 -> 0.16969048 | K17: =SUM('P&L'!K7:K9)/'P&L'!K5 -> 0.16799534 | M17: =IFERROR(AVERAGE(C17:K17),0) -> 0.1879661 | N17: =IFERROR(MEDIAN(C17:K17),0) -> 0.18235886
B18: Depreciation as % of sales | C18: =SUM(Assumptions!C48:C49)/'P&L'!C5 -> 0.41884451 | D18: =SUM(Assumptions!D48:D49)/'P&L'!D5 -> 0.45429588 | E18: =SUM(Assumptions!E48:E49)/'P&L'!E5 -> 0.43158248 | F18: =SUM(Assumptions!F48:F49)/'P&L'!F5 -> 0.40077036 | G18: =SUM(Assumptions!G48:G49)/'P&L'!G5 -> 0.34191083 | H18: =SUM(Assumptions!H48:H49)/'P&L'!H5 -> 0.32553636 | I18: =SUM(Assumptions!I48:I49)/'P&L'!I5 -> 0.33164634 | J18: =SUM(Assumptions!J48:J49)/'P&L'!J5 -> 0.34475172 | K18: =SUM(Assumptions!K48:K49)/'P&L'!K5 -> 0.34134558 | M18: =IFERROR(AVERAGE(C18:K18),0) -> 0.37674267 | N18: =IFERROR(MEDIAN(C18:K18),0) -> 0.34475172
B20: Return on Capital Employed | C20: ='P&L'!C10/SUM(BS!C28+BS!C25) -> 0.3309451 | D20: ='P&L'!D10/SUM(BS!D28+BS!D25) -> 0.29661033 | E20: ='P&L'!E10/SUM(BS!E28+BS!E25) -> 0.36052419 | F20: ='P&L'!F10/SUM(BS!F28+BS!F25) -> 0.51956938 | G20: ='P&L'!G10/SUM(BS!G28+BS!G25) -> 0.68075453 | H20: ='P&L'!H10/SUM(BS!H28+BS!H25) -> 0.84298557 | I20: ='P&L'!I10/SUM(BS!I28+BS!I25) -> 0.93061579 | J20: ='P&L'!J10/SUM(BS!J28+BS!J25) -> 0.99474795 | K20: ='P&L'!K10/SUM(BS!K28+BS!K25) -> 1.105773 | M20: =IFERROR(AVERAGE(C20:K20),0) -> 0.67361399 | N20: =IFERROR(MEDIAN(C20:K20),0) -> 0.68075453
B21: Return on Equity% | C21: ='P&L'!C16/BS!C28 -> 1.2712512 | D21: ='P&L'!D16/BS!D28 -> 0.96858785 | E21: ='P&L'!E16/BS!E28 -> 1.0510805 | F21: ='P&L'!F16/BS!F28 -> 1.393387 | G21: ='P&L'!G16/BS!G28 -> 1.9743226 | H21: ='P&L'!H16/BS!H28 -> 2.416234 | I21: ='P&L'!I16/BS!I28 -> 2.6243786 | J21: ='P&L'!J16/BS!J28 -> 2.7566725 | K21: ='P&L'!K16/BS!K28 -> 3.0115327 | M21: =IFERROR(AVERAGE(C21:K21),0) -> 1.9408274 | N21: =IFERROR(MEDIAN(C21:K21),0) -> 1.9743226
B22: Self Sustained Growth Rate | C22: =C21 -> 1.2712512 | D22: =D21 -> 0.96858785 | E22: =E21 -> 1.0510805 | F22: =F21 -> 1.393387 | G22: =G21 -> 1.9743226 | H22: =H21 -> 2.416234 | I22: =I21 -> 2.6243786 | J22: =J21 -> 2.7566725 | K22: =K21 -> 3.0115327 | M22: =IFERROR(AVERAGE(C22:K22),0) -> 1.9408274 | N22: =IFERROR(MEDIAN(C22:K22),0) -> 1.9743226
B23: Interest Coverage Ratio | C23: ='P&L'!C10/-'P&L'!C12 -> 8.0908401 | D23: ='P&L'!D10/-'P&L'!D12 -> 7.9761191 | E23: ='P&L'!E10/-'P&L'!E12 -> 9.93676 | F23: ='P&L'!F10/-'P&L'!F12 -> 14.494414 | G23: ='P&L'!G10/-'P&L'!G12 -> 19.7688 | H23: ='P&L'!H10/-'P&L'!H12 -> 24.705274 | I23: ='P&L'!I10/-'P&L'!I12 -> 27.428298 | J23: ='P&L'!J10/-'P&L'!J12 -> 29.626845 | K23: ='P&L'!K10/-'P&L'!K12 -> 33.186762 | M23: =IFERROR(AVERAGE(C23:K23),0) -> 19.468235 | N23: =IFERROR(MEDIAN(C23:K23),0) -> 19.7688
B25: Debtor Turnover Ratio | D25: ='P&L'!D5/AVERAGE(Assumptions!C76:D76) -> 35.261245 | E25: ='P&L'!E5/AVERAGE(Assumptions!D76:E76) -> 29.634454 | F25: ='P&L'!F5/AVERAGE(Assumptions!E76:F76) -> 29.744959 | G25: ='P&L'!G5/AVERAGE(Assumptions!F76:G76) -> 32.509185 | H25: ='P&L'!H5/AVERAGE(Assumptions!G76:H76) -> 32.478295 | I25: ='P&L'!I5/AVERAGE(Assumptions!H76:I76) -> 31.630198 | J25: ='P&L'!J5/AVERAGE(Assumptions!I76:J76) -> 31.715293 | K25: ='P&L'!K5/AVERAGE(Assumptions!J76:K76) -> 31.711198 | M25: =IFERROR(AVERAGE(D25:K25),0) -> 31.835603 | N25: =IFERROR(MEDIAN(D25:K25),0) -> 31.713245
B26: Creditor Turnover Ratio | D26: =Assumptions!D50/AVERAGE(Assumptions!C71:D71) -> 25.405349 | E26: =Assumptions!E50/AVERAGE(Assumptions!D71:E71) -> 27.789162 | F26: =Assumptions!F50/AVERAGE(Assumptions!E71:F71) -> 25.54264 | G26: =Assumptions!G50/AVERAGE(Assumptions!F71:G71) -> 25.45737 | H26: =Assumptions!H50/AVERAGE(Assumptions!G71:H71) -> 27.304858 | I26: =Assumptions!I50/AVERAGE(Assumptions!H71:I71) -> 27.539326 | J26: =Assumptions!J50/AVERAGE(Assumptions!I71:J71) -> 27.488295 | K26: =Assumptions!K50/AVERAGE(Assumptions!J71:K71) -> 27.230664 | M26: =IFERROR(AVERAGE(D26:K26),0) -> 26.719708 | N26: =IFERROR(MEDIAN(D26:K26),0) -> 27.267761
B27: Fixed Asset Turnover | D27: ='P&L'!D5/AVERAGE(BS!C12:D12) -> 23.232122 | E27: ='P&L'!E5/AVERAGE(BS!D12:E12) -> 23.340337 | F27: ='P&L'!F5/AVERAGE(BS!E12:F12) -> 25.282618 | G27: ='P&L'!G5/AVERAGE(BS!F12:G12) -> 26.621071 | H27: ='P&L'!H5/AVERAGE(BS!G12:H12) -> 26.877386 | I27: ='P&L'!I5/AVERAGE(BS!H12:I12) -> 26.801039 | J27: ='P&L'!J5/AVERAGE(BS!I12:J12) -> 26.507717 | K27: ='P&L'!K5/AVERAGE(BS!J12:K12) -> 26.178029 | M27: =IFERROR(AVERAGE(D27:K27),0) -> 25.60504 | N27: =IFERROR(MEDIAN(D27:K27),0) -> 26.342873
B28: Capital Turnover Ratio | C28: ='P&L'!C5/SUM(BS!C28,BS!C25) -> 1.5866239 | D28: ='P&L'!D5/SUM(BS!D28,BS!D25) -> 1.6647932 | E28: ='P&L'!E5/SUM(BS!E28,BS!E25) -> 1.7483548 | F28: ='P&L'!F5/SUM(BS!F28,BS!F25) -> 1.9451391 | G28: ='P&L'!G5/SUM(BS!G28,BS!G25) -> 2.1036409 | H28: ='P&L'!H5/SUM(BS!H28,BS!H25) -> 2.400881 | I28: ='P&L'!I5/SUM(BS!I28,BS!I25) -> 2.667689 | J28: ='P&L'!J5/SUM(BS!J28,BS!J25) -> 2.9380572 | K28: ='P&L'!K5/SUM(BS!K28,BS!K25) -> 3.2370919 | M28: =IFERROR(AVERAGE(C28:K28),0) -> 2.2546968 | N28: =IFERROR(MEDIAN(C28:K28),0) -> 2.1036409
B30: Debtor Days | D30: =365/D25 -> 10.351308 | E30: =365/E25 -> 12.316745 | F30: =365/F25 -> 12.270987 | G30: =365/G25 -> 11.227596 | H30: =365/H25 -> 11.238275 | I30: =365/I25 -> 11.539605 | J30: =365/J25 -> 11.508644 | K30: =365/K25 -> 11.51013 | M30: =IFERROR(AVERAGE(C30:H30),0) -> 11.480982 | N30: =IFERROR(MEDIAN(C30:H30),0) -> 11.238275
B31: Payable Days | D31: =365/D26 -> 14.367053 | E31: =365/E26 -> 13.134617 | F31: =365/F26 -> 14.28983 | G31: =365/G26 -> 14.337694 | H31: =365/H26 -> 13.367585 | I31: =365/I26 -> 13.253774 | J31: =365/J26 -> 13.278379 | K31: =365/K26 -> 13.404007 | M31: =IFERROR(AVERAGE(C31:H31),0) -> 13.899356 | N31: =IFERROR(MEDIAN(C31:H31),0) -> 14.28983
B32: Cash Conversion Cycle days | D32: =D30-D31 -> -4.0157455 | E32: =E30-E31 -> -0.81787253 | F32: =F30-F31 -> -2.0188437 | G32: =G30-G31 -> -3.1100982 | H32: =H30-H31 -> -2.1293099 | I32: =I30-I31 -> -1.7141687 | J32: =J30-J31 -> -1.7697354 | K32: =K30-K31 -> -1.8938769 | M32: =IFERROR(AVERAGE(C32:H32),0) -> -2.418374 | N32: =IFERROR(MEDIAN(C32:H32),0) -> -2.1293099
